Workbook

Sheet  P&L
A1: JSW | B1: Rs Cr | C1: 43921 | D1: 44286 | E1: 44651 | F1: 45016 | G1: 45382 | H1: 45747 | I1: 46112 | K1: 5 YEARS | L1: 3 YEARS | M1: TATA | O1: Rs Cr | P1: 43921 | Q1: 44286 | R1: 44651 | S1: 45016 | T1: 45382 | U1: 45747 | V1: 46112 | X1: 5 YEARS | Y1: 3 YEARS | Z1: JINDAL | AB1: Rs Cr | AC1: 43921 | AD1: 44286 | AE1: 44651 | AF1: 45016 | AG1: 45382 | AH1: 45747 | AI1: 46112 | AK1: 5 YEARS | AL1: 3 YEARS
B2: Sales | C2: 73326 | D2: 79839 | E2: 146371 | F2: 165960 | G2: 175006 | H2: 168824 | I2: 185470 | K2: =(I2/D2)^(1/5)-1 -> 0.18361842 | L2: =(I2/F2)^(1/3)-1 -> 0.037743644 | O2: Sales | P2: 139816.65 | Q2: 156477.4 | R2: 243959.17 | S2: 243352.69 | T2: 229170.78 | U2: 218542.51 | V2: 232139.94 | X2: =(V2/Q2)^(1/5)-1 -> 0.082080696 | Y2: =(V2/S2)^(1/3)-1 -> -0.01560083 | AB2: Sales | AC2: 37923.19 | AD2: 34578.9 | AE2: 51165.64 | AF2: 53211.52 | AG2: 50354.45 | AH2: 50128.66 | AI2: 53454.85 | AK2: =(AI2/AD2)^(1/5)-1 -> 0.091026221 | AL2: =(AI2/AF2)^(1/3)-1 -> 0.0015219764
B3: % Growth YOY | C3: -0.13486792 | D3: =D2/C2-1 -> 0.088822519 | E3: =E2/D2-1 -> 0.83332707 | F3: =F2/E2-1 -> 0.13383116 | G3: =G2/F2-1 -> 0.05450711 | H3: =H2/G2-1 -> -0.035324503 | I3: =I2/H2-1 -> 0.098599725 | O3: % Growth YOY | Q3: =Q2/P2-1 -> 0.11916142 | R3: =R2/Q2-1 -> 0.55906968 | S3: =S2/R2-1 -> -0.0024859898 | T3: =T2/S2-1 -> -0.058277186 | U3: =U2/T2-1 -> -0.046377073 | V3: =V2/U2-1 -> 0.062218696 | AB3: % Growth YOY | AC3: -0.19253503 | AD3: =AD2/AC2-1 -> -0.088185883 | AE3: =AE2/AD2-1 -> 0.47967807 | AF3: =AF2/AE2-1 -> 0.039985428 | AG3: =AG2/AF2-1 -> -0.053692697 | AH3: =AH2/AG2-1 -> -0.0044840128 | AI3: =AI2/AH2-1 -> 0.06635306
B4: Expenses | C4: 61513 | D4: 59661 | E4: 107257 | F4: 147490 | G4: 146849 | H4: 146099 | I4: 156006 | K4: 0.21196521 | L4: 0.018887518 | O4: Expenses | P4: 122353.59 | Q4: 125973.14 | R4: 180469.22 | S4: 211052.53 | T4: 206922.86 | U4: 193244.06 | V4: 197787.5 | X4: 0.21196521 | Y4: 0.018887518 | AB4: Expenses | AC4: 31092.14 | AD4: 21472.14 | AE4: 35606.72 | AF4: 43269.58 | AG4: 40152.89 | AH4: 40640.37 | AI4: 43750.76 | AK4: 0.21196521 | AL4: 0.018887518
B5: Material Cost (% of Sales) | C5: 0.53187137 | D5: 0.4115282 | E5: 0.42953181 | F5: 0.57827187 | G5: 0.54143287 | H5: 0.52817727 | I5: 0.49534696 | O5: Material Cost (% of Sales) | P5: 0.41511501 | Q5: 0.3521327 | R5: 0.37332727 | S5: 0.47912842 | T5: 0.42547479 | U5: 0.43514326 | V5: 0.39901824 | AB5: Material Cost (% of Sales) | AC5: 0.29977647 | AD5: 0.31390819 | AE5: 0.41588378 | AF5: 0.46685868 | AG5: 0.43821589 | AH5: 0.44873113 | AI5: 0.49415834
B6: COGS | C6: =C2*C5 -> 39000 | D6: =D2*D5 -> 32856 | E6: =E2*E5 -> 62871 | F6: =F2*F5 -> 95970 | G6: =G2*G5 -> 94754 | H6: =H2*H5 -> 89169 | I6: =I2*I5 -> 91872 | O6: COGS | P6: =P2*P5 -> 58039.99 | Q6: =Q2*Q5 -> 55100.81 | R6: =R2*R5 -> 91076.61 | S6: =S2*S5 -> 116597.19 | T6: =T2*T5 -> 97506.39 | U6: =U2*U5 -> 95097.3 | V6: =V2*V5 -> 92628.07 | AB6: COGS | AC6: =AC2*AC5 -> 11368.48 | AD6: =AD2*AD5 -> 10854.6 | AE6: =AE2*AE5 -> 21278.96 | AF6: =AF2*AF5 -> 24842.26 | AG6: =AG2*AG5 -> 22066.12 | AH6: =AH2*AH5 -> 22494.29 | AI6: =AI2*AI5 -> 26415.16
B7: Power and Fuel | C7: 0.085535826 | D7: 0.074963364 | E7: 0.077125933 | F7: 0.10515787 | G7: 0.086437036 | H7: 0.095726911 | I7: 0.08708686 | O7: Power and Fuel | P7: 0.03804926 | Q7: 0.036480795 | R7: 0.032908335 | S7: 0.039148571 | T7: 0.072490088 | U7: 0.060056279 | V7: 0.061743576 | AB7: Power and Fuel | AC7: 0.15925454 | AD7: 0.11669168 | AE7: 0.11396574 | AF7: 0.14300456 | AG7: 0.13449914 | AH7: 0.1100185 | AI7: 0.10975449
B8: Other Mfr. Exp | C8: 0.13969124 | D8: 0.20349704 | E8: 0.20308668 | F8: 0.15801398 | G8: 0.16979989 | H8: 0.17148036 | I8: 0.14904297 | O8: Other Mfr. Exp | P8: 0.15186096 | Q8: 0.13257461 | R8: 0.11819215 | S8: 0.1362008 | T8: 0.17505247 | U8: 0.17708454 | V8: 0.16148001 | AB8: Other Mfr. Exp | AC8: 0.091591187 | AD8: 0.090881723 | AE8: 0.091250691 | AF8: 0.12524919 | AG8: 0.13217005 | AH8: 0.13602977 | AI8: 0.13649781
B9: Employee Cost | C9: 0.038717508 | D9: 0.031388169 | E9: 0.023864017 | F9: 0.023590022 | G9: 0.026233386 | H9: 0.02842013 | I9: 0.028495174 | O9: Employee Cost | P9: 0.13255632 | Q9: 0.12723122 | R9: 0.095360629 | S9: 0.092126863 | T9: 0.10694897 | U9: 0.11388626 | V9: 0.11199701 | AB9: Employee Cost | AC9: 0.024088691 | AD9: 0.023752346 | AE9: 0.017038192 | AF9: 0.021343686 | AG9: 0.025610448 | AH9: 0.023662911 | AI9: 0.023438659
B10: Selling and Admin Cost | C10: 0.0061369773 | D10: 0.0050601836 | E10: 0.0038053986 | F10: 0.0061340082 | G10: 0.0051083963 | H10: 0.0054020755 | I10: 0.0053162236 | O10: Selling and Admin Cost | P10: 0.11156804 | Q10: 0.11189967 | R10: 0.11250108 | S10: 0.10486804 | T10: 0.063068992 | U10: 0.055537296 | V10: 0.057504064 | AB10: Selling and Admin Cost | AC10: 0.038279744 | AD10: 0.057128769 | AE10: 0.061973621 | AF10: 0.051324037 | AG10: 0.048929936 | AH10: 0.05294955 | AI10: 0.061684393
B11: Gross Profit | C11: =C2-C6 -> 34326 | D11: =D2-D6 -> 46983 | E11: =E2-E6 -> 83500 | F11: =F2-F6 -> 69990 | G11: =G2-G6 -> 80252 | H11: =H2-H6 -> 79655 | I11: =I2-I6 -> 93598 | K11: =(I11/D11)^(1/5)-1 -> 0.14779721 | L11: =(I11/F11)^(1/3)-1 -> 0.10173427 | O11: Gross Profit | P11: =P2-P6 -> 81776.66 | Q11: =Q2-Q6 -> 101376.59 | R11: =R2-R6 -> 152882.56 | S11: =S2-S6 -> 126755.5 | T11: =T2-T6 -> 131664.39 | U11: =U2-U6 -> 123445.21 | V11: =V2-V6 -> 139511.87 | X11: =(V11/Q11)^(1/5)-1 -> 0.065944753 | Y11: =(V11/S11)^(1/3)-1 -> 0.032479528 | AB11: Gross Profit | AC11: =AC2-AC6 -> 26554.71 | AD11: =AD2-AD6 -> 23724.3 | AE11: =AE2-AE6 -> 29886.68 | AF11: =AF2-AF6 -> 28369.26 | AG11: =AG2-AG6 -> 28288.33 | AH11: =AH2-AH6 -> 27634.37 | AI11: =AI2-AI6 -> 27039.69 | AK11: =(AI11/AD11)^(1/5)-1 -> 0.026506397 | AL11: =(AI11/AF11)^(1/3)-1 -> -0.015872804
B12: Gross Profit Margin | C12: =C11/C2 -> 0.46812863 | D12: =D11/D2 -> 0.5884718 | E12: =E11/E2 -> 0.57046819 | F12: =F11/F2 -> 0.42172813 | G12: =G11/G2 -> 0.45856713 | H12: =H11/H2 -> 0.47182273 | I12: =I11/I2 -> 0.50465304 | O12: Gross Profit Margin | P12: =P11/P2 -> 0.58488499 | Q12: =Q11/Q2 -> 0.6478673 | R12: =R11/R2 -> 0.62667273 | S12: =S11/S2 -> 0.52087158 | T12: =T11/T2 -> 0.57452521 | U12: =U11/U2 -> 0.56485674 | V12: =V11/V2 -> 0.60098176 | AB12: Gross Profit Margin | AC12: =AC11/AC2 -> 0.70022353 | AD12: =AD11/AD2 -> 0.68609181 | AE12: =AE11/AE2 -> 0.58411622 | AF12: =AF11/AF2 -> 0.53314132 | AG12: =AG11/AG2 -> 0.56178411 | AH12: =AH11/AH2 -> 0.55126887 | AI12: =AI11/AI2 -> 0.50584166
B13: EBITDA | C13: =C2-C4 -> 11813 | D13: =D2-D4 -> 20178 | E13: =E2-E4 -> 39114 | F13: =F2-F4 -> 18470 | G13: =G2-G4 -> 28157 | H13: =H2-H4 -> 22725 | I13: =I2-I4 -> 29464 | K13: =(I13/D13)^(1/5)-1 -> 0.078655389 | L13: =(I13/F13)^(1/3)-1 -> 0.16844499 | O13: EBITDA | P13: =P2-P4 -> 17463.06 | Q13: =Q2-Q4 -> 30504.26 | R13: =R2-R4 -> 63489.95 | S13: =S2-S4 -> 32300.16 | T13: =T2-T4 -> 22247.92 | U13: =U2-U4 -> 25298.45 | V13: =V2-V4 -> 34352.44 | X13: =(V13/Q13)^(1/5)-1 -> 0.024045891 | Y13: =(V13/S13)^(1/3)-1 -> 0.020745887 | AB13: EBITDA | AC13: =AC2-AC4 -> 6831.05 | AD13: =AD2-AD4 -> 13106.76 | AE13: =AE2-AE4 -> 15558.92 | AF13: =AF2-AF4 -> 9941.94 | AG13: =AG2-AG4 -> 10201.56 | AH13: =AH2-AH4 -> 9488.29 | AI13: =AI2-AI4 -> 9704.09 | AK13: =(AI13/AD13)^(1/5)-1 -> -0.058344833 | AL13: =(AI13/AF13)^(1/3)-1 -> -0.0080390878
B14: % Growth YOY | D14: =D13/C13-1 -> 0.70811817 | E14: =E13/D13-1 -> 0.93844781 | F14: =F13/E13-1 -> -0.52779056 | G14: =G13/F13-1 -> 0.52447212 | H14: =H13/G13-1 -> -0.19291828 | I14: =I13/H13-1 -> 0.29654565 | O14: % Growth YOY | Q14: =Q13/P13-1 -> 0.74678779 | R14: =R13/Q13-1 -> 1.081347 | S14: =S13/R13-1 -> -0.49125555 | T14: =T13/S13-1 -> -0.31121332 | U14: =U13/T13-1 -> 0.13711529 | V14: =V13/U13-1 -> 0.35788714 | AB14: % Growth YOY | AD14: =AD13/AC13-1 -> 0.91870357 | AE14: =AE13/AD13-1 -> 0.18709124 | AF14: =AF13/AE13-1 -> -0.36101349 | AG14: =AG13/AF13-1 -> 0.026113616 | AH14: =AH13/AG13-1 -> -0.069917738 | AI14: =AI13/AH13-1 -> 0.022743824
B15: EBITDA Margins | C15: =C13/C2 -> 0.16110247 | D15: =D13/D2 -> 0.25273363 | E15: =E13/E2 -> 0.26722507 | F15: =F13/F2 -> 0.11129188 | G15: =G13/G2 -> 0.16089163 | H15: =H13/H2 -> 0.13460764 | I15: =I13/I2 -> 0.15886127 | O15: EBITDA Margins | P15: =P13/P2 -> 0.12489972 | Q15: =Q13/Q2 -> 0.19494355 | R15: =R13/R2 -> 0.26024826 | S15: =S13/S2 -> 0.13272983 | T15: =T13/T2 -> 0.09708009 | U15: =U13/U2 -> 0.11575986 | V15: =V13/V2 -> 0.1479816 | AB15: EBITDA Margins | AC15: =AC13/AC2 -> 0.18012857 | AD15: =AD13/AD2 -> 0.37903924 | AE15: =AE13/AE2 -> 0.30408923 | AF15: =AF13/AF2 -> 0.18683811 | AG15: =AG13/AG2 -> 0.202595 | AH15: =AH13/AH2 -> 0.18927875 | AI15: =AI13/AI2 -> 0.18153806
B16: Other Income | C16: -289 | D16: 473 | E16: 1600 | F16: 1561 | G16: 1500 | H16: 73 | I16: 18489 | K16: =(I16/D16)^(1/5)-1 -> 1.0816632 | L16: =(I16/F16)^(1/3)-1 -> 1.2794855 | O16: Other Income | P16: -2883.63 | Q16: 179.78 | R16: 1299.99 | S16: 1568.86 | T16: -6005.23 | U16: 876.7 | V16: 737.82 | X16: =(V16/Q16)^(1/5)-1 -> 0.32630012 | Y16: =(V16/S16)^(1/3)-1 -> -0.22234182 | AB16: Other Income | AC16: 74.45 | AD16: -1861.44 | AE16: -1883.94 | AF16: -538.73 | AG16: 155.69 | AH16: -1065.11 | AI16: -602.85 | AK16: =(AI16/AD16)^(1/5)-1 -> -0.20187292 | AL16: =(AI16/AF16)^(1/3)-1 -> 0.038196041
B17: Other Income as % of Sales | C17: =C16/C2 -> -0.0039413032 | D17: =D16/D2 -> 0.0059244229 | E17: =E16/E2 -> 0.010931127 | F17: =F16/F2 -> 0.0094058809 | G17: =G16/G2 -> 0.0085711347 | H17: =H16/H2 -> 0.00043240298 | I17: =I16/I2 -> 0.099687281 | O17: Other Income as % of Sales | P17: =P16/P2 -> -0.020624368 | Q17: =Q16/Q2 -> 0.0011489199 | R17: =R16/R2 -> 0.0053287196 | S17: =S16/S2 -> 0.006446857 | T17: =T16/T2 -> -0.02620417 | U17: =U16/U2 -> 0.0040115765 | V17: =V16/V2 -> 0.0031783415 | AB17: Other Income as % of Sales | AC17: =AC16/AC2 -> 0.0019631787 | AD17: =AD16/AD2 -> -0.053831672 | AE17: =AE16/AE2 -> -0.036820413 | AF17: =AF16/AF2 -> -0.010124311 | AG17: =AG16/AG2 -> 0.0030918817 | AH17: =AH16/AH2 -> -0.021247526 | AI17: =AI16/AI2 -> -0.011277742
B18: Depreciation | C18: 4246 | D18: 4679 | E18: 6001 | F18: 7474 | G18: 8172 | H18: 9309 | I18: 9601 | K18: =(I18/D18)^(1/5)-1 -> 0.15460301 | L18: =(I18/F18)^(1/3)-1 -> 0.087062361 | O18: Depreciation | P18: 8440.73 | Q18: 9233.64 | R18: 9100.87 | S18: 9335.2 | T18: 9882.16 | U18: 10421.33 | V18: 11954.51 | X18: =(V18/Q18)^(1/5)-1 -> 0.053008237 | Y18: =(V18/S18)^(1/3)-1 -> 0.085932217 | AB18: Depreciation | AC18: 3428.87 | AD18: 2414.13 | AE18: 2096.78 | AF18: 2690.95 | AG18: 2821.75 | AH18: 2767.55 | AI18: 3171.45 | AK18: =(AI18/AD18)^(1/5)-1 -> 0.056086384 | AL18: =(AI18/AF18)^(1/3)-1 -> 0.056292218
B19: EBIT | C19: =C13-C18 -> 7567 | D19: =D13-D18 -> 15499 | E19: =E13-E18 -> 33113 | F19: =F13-F18 -> 10996 | G19: =G13-G18 -> 19985 | H19: =H13-H18 -> 13416 | I19: =I13-I18 -> 19863 | O19: EBIT | P19: =P13-P18 -> 9022.33 | Q19: =Q13-Q18 -> 21270.62 | R19: =R13-R18 -> 54389.08 | S19: =S13-S18 -> 22964.96 | T19: =T13-T18 -> 12365.76 | U19: =U13-U18 -> 14877.12 | V19: =V13-V18 -> 22397.93 | AB19: EBIT | AC19: =AC13-AC18 -> 3402.18 | AD19: =AD13-AD18 -> 10692.63 | AE19: =AE13-AE18 -> 13462.14 | AF19: =AF13-AF18 -> 7250.99 | AG19: =AG13-AG18 -> 7379.81 | AH19: =AH13-AH18 -> 6720.74 | AI19: =AI13-AI18 -> 6532.64
B20: EBIT Margin | C20: =C19/C2 -> 0.10319668 | D20: =D19/D2 -> 0.19412818 | E20: =E19/E2 -> 0.22622651 | F20: =F19/F2 -> 0.066256929 | G20: =G19/G2 -> 0.11419608 | H20: =H19/H2 -> 0.079467374 | I20: =I19/I2 -> 0.10709549 | P20: =P19/P2 -> 0.064529725 | Q20: =Q19/Q2 -> 0.13593413 | R20: =R19/R2 -> 0.22294337 | S20: =S19/S2 -> 0.094369041 | T20: =T19/T2 -> 0.053958711 | U20: =U19/U2 -> 0.068074262 | V20: =V19/V2 -> 0.096484603 | AB20: EBIT Margin | AC20: =AC19/AC2 -> 0.08971239 | AD20: =AD19/AD2 -> 0.30922412 | AE20: =AE19/AE2 -> 0.26310899 | AF20: =AF19/AF2 -> 0.1362673 | AG20: =AG19/AG2 -> 0.14655726 | AH20: =AH19/AH2 -> 0.13406981 | AI20: =AI19/AI2 -> 0.12220856
B21: Interest | C21: 4265 | D21: 3957 | E21: 4968 | F21: 6902 | G21: 8105 | H21: 8412 | I21: 9102 | K21: =(I21/D21)^(1/5)-1 -> 0.18128355 | L21: =(I21/F21)^(1/3)-1 -> 0.096614436 | O21: Interest | P21: 7533.46 | Q21: 7606.71 | R21: 5462.2 | S21: 6298.7 | T21: 7507.57 | U21: 7340.95 | V21: 7167.06 | X21: =(V21/Q21)^(1/5)-1 -> -0.011836436 | Y21: =(V21/S21)^(1/3)-1 -> 0.043990882 | AB21: Interest | AC21: 3767.88 | AD21: 2753.34 | AE21: 1887.71 | AF21: 1445.89 | AG21: 1294.23 | AH21: 1312.08 | AI21: 1516.64 | AK21: =(AI21/AD21)^(1/5)-1 -> -0.11242608 | AL21: =(AI21/AF21)^(1/3)-1 -> 0.016051569
D22: =D21/C21-1 -> -0.072215709 | E22: =E21/D21-1 -> 0.25549659 | F22: =F21/E21-1 -> 0.38929147 | G22: =G21/F21-1 -> 0.17429731 | H22: =H21/G21-1 -> 0.037877853 | I22: =I21/H21-1 -> 0.082025678
B23: Interest Coverage(Times) | C23: =C19/C21 -> 1.7742087 | D23: =D19/D21 -> 3.9168562 | E23: =E19/E21 -> 6.6652576 | F23: =F19/F21 -> 1.5931614 | G23: =G19/G21 -> 2.4657619 | H23: =H19/H21 -> 1.5948645 | I23: =I19/I21 -> 2.1822676 | K23: =(I23/D23)^(1/5)-1 -> -0.11040143 | L23: =(I23/F23)^(1/3)-1 -> 0.11057888 | O23: Interest Coverage(Times) | P23: =P19/P21 -> 1.1976343 | Q23: =Q19/Q21 -> 2.796297 | R23: =R19/R21 -> 9.9573578 | S23: =S19/S21 -> 3.6459841 | T23: =T19/T21 -> 1.6471055 | U23: =U19/U21 -> 2.0265933 | V23: =V19/V21 -> 3.125121 | X23: =(V23/Q23)^(1/5)-1 -> 0.022484447 | Y23: =(V23/S23)^(1/3)-1 -> -0.050086577 | AB23: Interest Coverage(Times) | AC23: =AC19/AC21 -> 0.90294277 | AD23: =AD19/AD21 -> 3.8835124 | AE23: =AE19/AE21 -> 7.1314662 | AF23: =AF19/AF21 -> 5.0148974 | AG23: =AG19/AG21 -> 5.7020854 | AH23: =AH19/AH21 -> 5.1222029 | AI23: =AI19/AI21 -> 4.3073109 | AK23: =(AI23/AD23)^(1/5)-1 -> 0.020930798 | AL23: =(AI23/AF23)^(1/3)-1 -> -0.049435942
B24: Profit before tax (PBT) | C24: =C19+C16-C21 -> 3013 | D24: =D19+D16-D21 -> 12015 | E24: =E19+E16-E21 -> 29745 | F24: =F19+F16-F21 -> 5655 | G24: =G19+G16-G21 -> 13380 | H24: =H19+H16-H21 -> 5077 | I24: =I19+I16-I21 -> 29250 | K24: =(I24/D24)^(1/5)-1 -> 0.1947593 | L24: =(I24/F24)^(1/3)-1 -> 0.72940916 | O24: Profit before tax (PBT) | P24: =P19+P16-P21 -> -1394.76 | Q24: =Q19+Q16-Q21 -> 13843.69 | R24: =R19+R16-R21 -> 50226.87 | S24: =S19+S16-S21 -> 18235.12 | T24: =T19+T16-T21 -> -1147.04 | U24: =U19+U16-U21 -> 8412.87 | V24: =V19+V16-V21 -> 15968.69 | X24: =(V24/Q24)^(1/5)-1 -> 0.028971829 | Y24: =(V24/S24)^(1/3)-1 -> -0.043275516 | AB24: Profit before tax (PBT) | AC24: =AC19+AC16-AC21 -> -291.25 | AD24: =AD19+AD16-AD21 -> 6077.85 | AE24: =AE19+AE16-AE21 -> 9690.49 | AF24: =AF19+AF16-AF21 -> 5266.37 | AG24: =AG19+AG16-AG21 -> 6241.27 | AH24: =AH19+AH16-AH21 -> 4343.55 | AI24: =AI19+AI16-AI21 -> 4413.15 | AK24: =(AI24/AD24)^(1/5)-1 -> -0.062006687 | AL24: =(AI24/AF24)^(1/3)-1 -> -0.057215486
B25: % Growth YOY | D25: =D24/C24-1 -> 2.9877199 | E25: =E24/D24-1 -> 1.4756554 | F25: =F24/E24-1 -> -0.80988401 | G25: =G24/F24-1 -> 1.3660477 | H25: =H24/G24-1 -> -0.62055306 | I25: =I24/H24-1 -> 4.7612763 | O25: % Growth YOY | Q25: =Q24/P24-1 -> -10.9255 | R25: =R24/Q24-1 -> 2.6281418 | S25: =S24/R24-1 -> -0.63694493 | T25: =T24/S24-1 -> -1.0629028 | U25: =U24/T24-1 -> -8.3344173 | V25: 0.89812632 | AB25: % Growth YOY | AC25: -0.89604489 | AD25: =AD24/AC24-1 -> -21.868155 | AE25: 0.5943944 | AF25: -0.45654245 | AG25: 0.18511802 | AH25: -0.30405991 | AI25: 0.016023759
B26: PBT Margin | C26: =C24/C2 -> 0.041090473 | D26: =D24/D2 -> 0.15049036 | E26: =E24/E2 -> 0.20321648 | F26: =F24/F2 -> 0.034074476 | G26: =G24/G2 -> 0.076454522 | H26: =H24/H2 -> 0.030072738 | I26: =I24/I2 -> 0.15770745 | K26: =(I26/D26)^(1/5)-1 -> 0.0094125556 | L26: =(I26/F26)^(1/3)-1 -> 0.66650903 | O26: PBT Margin | P26: =P24/P2 -> -0.0099756359 | Q26: =Q24/Q2 -> 0.088470859 | R26: =R24/R2 -> 0.20588228 | S26: =S24/S2 -> 0.074932889 | T26: =T24/T2 -> -0.0050051756 | U26: =U24/U2 -> 0.038495348 | V26: 0.068789067 | X26: =(V26/Q26)^(1/5)-1 -> -0.04908032 | Y26: =(V26/S26)^(1/3)-1 -> -0.028113277 | AB26: PBT Margin | AC26: =AC24/AC2 -> -0.0076799974 | AD26: 0.17576759 | AE26: 0.18939448 | AF26: 0.098970486 | AG26: 0.12394674 | AH26: 0.086648037 | AI26: 0.082558458 | AK26: =(AI26/AD26)^(1/5)-1 -> -0.14026511 | AL26: =(AI26/AF26)^(1/3)-1 -> -0.058648201
B27: Tax | C27: -906 | D27: 4142 | E27: 8807 | F27: 1516 | G27: 4407 | H27: 1586 | I27: 3742 | K27: =(I27/D27)^(1/5)-1 -> -0.020106814 | L27: =(I27/F27)^(1/3)-1 -> 0.35145481 | O27: Tax | P27: -2568.41 | Q27: 5653.9 | R27: 8477.55 | S27: 10159.77 | T27: 3762.57 | U27: 5239.09 | V27: 5082.87 | X27: =(V27/Q27)^(1/5)-1 -> -0.021068788 | Y27: =(V27/S27)^(1/3)-1 -> -0.20614404 | AB27: Tax | AC27: 108.45 | AD27: 1810.81 | AE27: 2924.53 | AF27: 1292.28 | AG27: 297.95 | AH27: 1497.87 | AI27: 1052.28 | AK27: =(AI27/AD27)^(1/5)-1 -> -0.10287763 | AL27: =(AI27/AF27)^(1/3)-1 -> -0.066190622
B28: Actual Tax Rate | C28: -0.30069698 | D28: 0.34473575 | E28: 0.29608338 | F28: 0.26808134 | G28: 0.3293722 | H28: 0.31238921 | I28: 0.12793162 | K28: =(I28/D28)^(1/5)-1 -> -0.1798405 | L28: =(I28/F28)^(1/3)-1 -> -0.21854536 | O28: Actual Tax Rate | P28: 1.8414709 | Q28: 0.4084099 | R28: 0.16878515 | S28: 0.557154 | T28: -3.2802431 | U28: 0.62274705 | V28: 0.31830225 | X28: =(V28/Q28)^(1/5)-1 -> -0.048631668 | Y28: =(V28/S28)^(1/3)-1 -> -0.17023556 | AB28: Actual Tax Rate | AC28: -0.37236052 | AD28: 0.29793595 | AE28: 0.30179382 | AF28: 0.24538344 | AG28: 0.047738681 | AH28: 0.34484926 | AI28: 0.23844193 | AK28: =(AI28/AD28)^(1/5)-1 -> -0.043572744 | AL28: =(AI28/AF28)^(1/3)-1 -> -0.0095198172
B29: Net profit | C29: =C24-C27 -> 3919 | D29: =D24-D27 -> 7873 | E29: =E24-E27 -> 20938 | F29: =F24-F27 -> 4139 | G29: =G24-G27 -> 8973 | H29: =H24-H27 -> 3491 | I29: =I24-I27 -> 25508 | K29: =(I29/D29)^(1/5)-1 -> 0.26504866 | L29: =(I29/F29)^(1/3)-1 -> 0.83341309 | O29: Net profit | P29: =P24-P27 -> 1173.65 | Q29: =Q24-Q27 -> 8189.79 | R29: =R24-R27 -> 41749.32 | S29: =S24-S27 -> 8075.35 | T29: =T24-T27 -> -4909.61 | U29: =U24-U27 -> 3173.78 | V29: =V24-V27 -> 10885.82 | X29: =(V29/Q29)^(1/5)-1 -> 0.058565356 | Y29: =(V29/S29)^(1/3)-1 -> 0.10467179 | AB29: Net profit | AC29: =AC24-AC27 -> -399.7 | AD29: =AD24-AD27 -> 4267.04 | AE29: =AE24-AE27 -> 6765.96 | AF29: =AF24-AF27 -> 3974.09 | AG29: =AG24-AG27 -> 5943.32 | AH29: =AH24-AH27 -> 2845.68 | AI29: =AI24-AI27 -> 3360.87 | AK29: =(AI29/AD29)^(1/5)-1 -> -0.046622277 | AL29: =(AI29/AF29)^(1/3)-1 -> -0.054333498
B30: % Growth YOY | D30: =D29/C29-1 -> 1.0089308 | E30: =E29/D29-1 -> 1.6594691 | F30: =F29/E29-1 -> -0.80232114 | G30: =G29/F29-1 -> 1.167915 | H30: =H29/G29-1 -> -0.61094394 | I30: =I29/H29-1 -> 6.3067889 | O30: % Growth YOY | P30: -0.87134092 | Q30: =Q29/P29-1 -> 5.9780514 | R30: =R29/Q29-1 -> 4.0977278 | S30: =S29/R29-1 -> -0.80657529 | T30: =T29/S29-1 -> -1.6079749 | U30: =U29/T29-1 -> -1.6464424 | V30: =V29/U29-1 -> 2.4299227 | AB30: % Growth YOY | AD30: =AD29/AC29-1 -> -11.675607 | AE30: =AE29/AD29-1 -> 0.58563313 | AF30: =AF29/AE29-1 -> -0.41263472 | AG30: =AG29/AF29-1 -> 0.49551721 | AH30: =AH29/AG29-1 -> -0.52119691 | AI30: =AI29/AH29-1 -> 0.18104284
B31: Net Profit Margin | C31: =C29/C2 -> 0.053446254 | D31: =D29/D2 -> 0.098610955 | E31: =E29/E2 -> 0.14304746 | F31: =F29/F2 -> 0.024939745 | G31: =G29/G2 -> 0.051272528 | H31: =H29/H2 -> 0.02067834 | I31: =I29/I2 -> 0.13753168 | K31: =(I31/D31)^(1/5)-1 -> 0.06879771 | L31: =(I31/F31)^(1/3)-1 -> 0.76673025 | O31: Net Profit Margin | P31: =P29/P2 -> 0.0083942077 | Q31: =Q29/Q2 -> 0.052338485 | R31: =R29/R2 -> 0.17113241 | S31: =S29/S2 -> 0.03318373 | T31: =T29/T2 -> -0.021423368 | U31: =U29/U2 -> 0.014522484 | V31: =V29/V2 -> 0.046893352 | X31: =(V31/Q31)^(1/5)-1 -> -0.021731595 | Y31: =(V31/S31)^(1/3)-1 -> 0.12217871 | AB31: Net Profit Margin | AC31: =AC29/AC2 -> -0.010539725 | AD31: =AD29/AD2 -> 0.12340011 | AE31: =AE29/AE2 -> 0.1322364 | AF31: =AF29/AF2 -> 0.074684768 | AG31: =AG29/AG2 -> 0.11802969 | AH31: =AH29/AH2 -> 0.056767526 | AI31: =AI29/AI2 -> 0.06287306 | AK31: =(AI31/AD31)^(1/5)-1 -> -0.12616424 | AL31: =(AI31/AF31)^(1/3)-1 -> -0.055770593
B32: EPS | C32: 16.212974 | D32: 32.570743 | E32: 86.620884 | F32: 17.123118 | G32: 36.691883 | H32: 14.275199 | I32: 104.30587 | K32: =(I32/D32)^(1/5)-1 -> 0.26210712 | L32: =(I32/F32)^(1/3)-1 -> 0.82631338 | O32: EPS | P32: 1.0418646 | Q32: 6.8442741 | R32: 34.184328 | S32: 6.607495 | T32: -3.9328794 | U32: 2.5423799 | V32: 8.7201666 | X32: =(V32/Q32)^(1/5)-1 -> 0.049637836 | Y32: =(V32/S32)^(1/3)-1 -> 0.096888913 | AB32: EPS | AC32: -3.9186275 | AD32: 41.833725 | AE32: 66.326439 | AF32: 38.957847 | AG32: 58.262131 | AH32: 27.896089 | AI32: 32.946476 | AK32: =(AI32/AD32)^(1/5)-1 -> -0.046640969 | AL32: =(AI32/AF32)^(1/3)-1 -> -0.054333498
B33: % Growth YOY | D33: =D32/C32-1 -> 1.0089308 | E33: =E32/D32-1 -> 1.6594691 | F33: =F32/E32-1 -> -0.80232114 | G33: =G32/F32-1 -> 1.1428272 | H33: =H32/G32-1 -> -0.61094394 | I33: =I32/H32-1 -> 6.3067889 | O33: % Growth YOY | Q33: =Q32/P32-1 -> 5.5692552 | R33: =R32/Q32-1 -> 3.9945878 | S33: =S32/R32-1 -> -0.80670982 | T33: =T32/S32-1 -> -1.5952149 | U33: =U32/T32-1 -> -1.6464424 | V33: =V32/U32-1 -> 2.4299227 | AB33: % Growth YOY | AD33: =AD32/AC32-1 -> -11.675607 | AE33: =AE32/AD32-1 -> 0.58547769 | AF33: =AF32/AE32-1 -> -0.41263472 | AG33: =AG32/AF32-1 -> 0.49551721 | AH33: =AH32/AG32-1 -> -0.52119691 | AI33: =AI32/AH32-1 -> 0.18104284
B34: Price to earning | C34: 9.0205537 | D34: 14.38254 | E34: 8.458122 | F34: 40.185439 | G34: 22.626258 | H34: 74.47882 | I34: 10.761619 | K34: =(I34/D34)^(1/5)-1 -> -0.056355515 | L34: =(I34/F34)^(1/3)-1 -> -0.35543068 | O34: Price to earning | P34: 25.876684 | Q34: 11.86247 | R34: 3.8239745 | S34: 15.815373 | T34: -39.627455 | U34: 60.667565 | V34: 22.001873 | X34: =(V34/Q34)^(1/5)-1 -> 0.13150611 | Y34: =(V34/S34)^(1/3)-1 -> 0.11633207 | AB34: Price to earning | AC34: -20.976733 | AD34: 8.2134688 | AE34: 8.0337496 | AF34: 14.020282 | AG34: 14.574647 | AH34: 32.70351 | AI34: 33.785101 | AK34: =(AI34/AD34)^(1/5)-1 -> 0.32690466 | AL34: =(AI34/AF34)^(1/3)-1 -> 0.34067288
B35: Price | C35: 146.25 | D35: 468.45 | E35: 732.65 | F35: 688.1 | G35: 830.2 | H35: 1063.2 | I35: 1122.5 | K35: =(I35/D35)^(1/5)-1 -> 0.19098042 | L35: =(I35/F35)^(1/3)-1 -> 0.17718557 | O35: Price | P35: 26.96 | Q35: 81.19 | R35: 130.72 | S35: 104.5 | T35: 155.85 | U35: 154.24 | V35: 191.86 | X35: =(V35/Q35)^(1/5)-1 -> 0.18767162 | Y35: =(V35/S35)^(1/3)-1 -> 0.22449228 | AB35: Price | AC35: 82.2 | AD35: 343.6 | AE35: 532.85 | AF35: 546.2 | AG35: 849.15 | AH35: 912.3 | AI35: 1113.1 | AK35: =(AI35/AD35)^(1/5)-1 -> 0.26501654 | AL35: =(AI35/AF35)^(1/3)-1 -> 0.26782943
B36: Market Cap | C36: 35351.55 | D36: 113233.73 | E36: 177096.16 | F36: 166327.53 | G36: 203025.41 | H36: 260005.56 | I36: 274507.38 | K36: =(I36/D36)^(1/5)-1 -> 0.19375619 | L36: =(I36/F36)^(1/3)-1 -> 0.18176183 | O36: Market Cap | P36: 30370.17 | Q36: 97151.142 | R36: 159648.34 | S36: 127714.68 | T36: 194555.35 | U36: 192545.5 | V36: 239508.43 | X36: =(V36/Q36)^(1/5)-1 -> 0.19777317 | Y36: =(V36/S36)^(1/3)-1 -> 0.23318055 | AB36: Market Cap | AC36: 8384.4 | AD36: 35047.2 | AE36: 54356.029 | AF36: 55717.862 | AG36: 86621.792 | AH36: 93063.723 | AI36: 113547.33 | AK36: =(AI36/AD36)^(1/5)-1 -> 0.26504135 | AL36: =(AI36/AF36)^(1/3)-1 -> 0.26782943
B39: No of equity shares | C39: 301 | D39: 302 | E39: 301 | F39: 301 | G39: 305 | H39: 305 | I39: 305 | O39: No of equity shares | P39: 1145 | Q39: 1198 | R39: 1221 | S39: 1221 | T39: 1247 | U39: 1247 | V39: 1247 | AB39: No of equity shares | AC39: 102 | AD39: 102 | AE39: 101 | AF39: 100 | AG39: 100 | AH39: 101 | AI39: 102
B40: Earning per share | C40: 16.212974 | D40: 32.570743 | E40: 86.620884 | F40: 17.123118 | G40: 36.691883 | H40: 14.275199 | I40: 104.30587 | O40: Earning per share | P40: =P32 -> 1.0418646 | Q40: =Q32 -> 6.8442741 | R40: =R32 -> 34.184328 | S40: =S32 -> 6.607495 | T40: =T32 -> -3.9328794 | U40: =U32 -> 2.5423799 | V40: =V32 -> 8.7201666 | AB40: Earning per share | AC40: =AC32 -> -3.9186275 | AD40: =AD32 -> 41.833725 | AE40: =AE32 -> 66.326439 | AF40: =AF32 -> 38.957847 | AG40: =AG32 -> 58.262131 | AH40: =AH32 -> 27.896089 | AI40: =AI32 -> 32.946476
B41: EPS growth | D41: =D40/C40-1 -> 1.0089308 | E41: =E40/D40-1 -> 1.6594691 | F41: =F40/E40-1 -> -0.80232114 | G41: =G40/F40-1 -> 1.1428272 | H41: =H40/G40-1 -> -0.61094394 | I41: =I40/H40-1 -> 6.3067889 | O41: EPS growth | Q41: =Q40/P40-1 -> 5.5692552 | R41: =R40/Q40-1 -> 3.9945878 | S41: =S40/R40-1 -> -0.80670982 | T41: =T40/S40-1 -> -1.5952149 | U41: =U40/T40-1 -> -1.6464424 | V41: =V40/U40-1 -> 2.4299227 | AB41: EPS growth | AD41: =AD40/AC40-1 -> -11.675607 | AE41: =AE40/AD40-1 -> 0.58547769 | AF41: =AF40/AE40-1 -> -0.41263472 | AG41: =AG40/AF40-1 -> 0.49551721 | AH41: =AH40/AG40-1 -> -0.52119691 | AI41: =AI40/AH40-1 -> 0.18104284
B43: Dividend per share | C43: =C40*C44 -> 2.4319461 | D43: =D40*D44 -> 8.1426858 | E43: =E40*E44 -> 21.655221 | F43: =F40*F44 -> 4.2807794 | G43: =G40*G44 -> 9.1729708 | H43: =H40*H44 -> 3.4260478 | I43: =I40*I44 -> 10.430587 | O43: Dividend per share | P43: =P40*P44 -> 0.77097977 | Q43: =Q40*Q44 -> 2.7377097 | R43: =R40*R44 -> 5.4694925 | S43: =S40*S44 -> 3.3037475 | T43: =T40*T44 -> 3.9722082 | U43: =U40*U44 -> 3.3305177 | V43: =V40*V44 -> 4.0112766 | AB43: Dividend per share | AC43: =AC40*AC44 -> 0 | AD43: =AD40*AD44 -> 0 | AE43: =AE40*AE44 -> 3.3163219 | AF43: =AF40*AF44 -> 2.3374708 | AG43: =AG40*AG44 -> 1.7478639 | AH43: =AH40*AH44 -> 1.9527262 | AI43: =AI40*AI44 -> 1.9767886
...

Sheet BALANCE SHEET
B1: JSW
B2: Rs Cr | C2: 43921 | D2: 44286 | E2: 44651 | F2: 45016 | G2: 45382 | H2: 45747 | I2: 46112
B3: Equity Share Capital | C3: 301 | D3: 302 | E3: 301 | F3: 301 | G3: 305 | H3: 305 | I3: 305
B4: Reserves | C4: 36298 | D4: 45308 | E4: 66996 | F4: 65394 | G4: 77364 | H4: 79191 | I4: 99748
B5: Borrowings | C5: 61423 | D5: 66727 | E5: 72237 | F5: 80853 | G5: 87984 | H5: 98752 | I5: 99310
B6: Other Liabilities | C6: 33798 | D6: 34826 | E6: 56951 | F6: 63991 | G6: 62245 | H6: 62197 | I6: 70295 | K6: Trade payables
B7: Total Liabilities | C7: 131820 | D7: 147163 | E7: 196485 | F7: 210539 | G7: 227898 | H7: 240445 | I7: 269658
B9: Net Block | C9: 62085 | D9: 64917 | E9: 99880 | F9: 104452 | G9: 112461 | H9: 124466 | I9: 117129
B10: Capital Work in Progress | C10: 27191 | D10: 32566 | E10: 16905 | F10: 22166 | G10: 29676 | H10: 21007 | I10: 22315
B11: Investments | C11: 1259 | D11: 7427 | E11: 4940 | F11: 4806 | G11: 7246 | H11: 15217 | I11: 10218
B12: Other Assets | C12: 41285 | D12: 42253 | E12: 74760 | F12: 79115 | G12: 78515 | H12: 79755 | I12: 119996 | K12: Cash
B13: Total Assets | C13: 131820 | D13: 147163 | E13: 196485 | F13: 210539 | G13: 227898 | H13: 240445 | I13: 269658
B15: Working Capital | C15: 7487 | D15: 7427 | E15: 17809 | F15: 15124 | G15: 16270 | H15: 17558 | I15: 49701 | K15: Effect CFO as well
B16: Debtors | C16: 4505 | D16: 4486 | E16: 7457 | F16: 7134 | G16: 7548 | H16: 8415 | I16: 11260 | K16: using suppliers money
B17: Inventory | C17: 13773 | D17: 14249 | E17: 33787 | F17: 33135 | G17: 37815 | H17: 34956 | I17: 32765
B18: Cash & Bank | C18: 12003 | D18: 12813 | E18: 17383 | F18: 20714 | G18: 12348 | H18: 13285 | I18: 40989 | K18: Investment sold
B20: TATA
B21: Rs Cr | C21: 43921 | D21: 44286 | E21: 44651 | F21: 45016 | G21: 45382 | H21: 45747 | I21: 46112
B22: Equity Share Capital | C22: 1144.95 | D22: 1197.61 | E22: 1221.21 | F22: 1221.24 | G22: 1247.44 | H22: 1247.44 | I22: 1247.44
B23: Reserves | C23: 72431.35 | D23: 73041.16 | E23: 113221.83 | F23: 101860.86 | G23: 90788.32 | H23: 89922.19 | I23: 100920.21
B24: Borrowings | C24: 116328.2 | D24: 88501.41 | E24: 75561.35 | F24: 84893.05 | G24: 87082.12 | H24: 94801.05 | I24: 92381.68
B25: Other Liabilities | C25: 59244.62 | D25: 81169.01 | E25: 92417.28 | F25: 97420.63 | G25: 90194.54 | H25: 89487.9 | I25: 101965.29
B26: Total Liabilities | C26: 249149.12 | D26: 243909.19 | E26: 282421.67 | F26: 285395.78 | G26: 269312.42 | H26: 275458.58 | I26: 296514.62
B28: Net Block | C28: 134550.66 | D28: 135775.18 | E28: 133287.83 | F28: 146621.46 | G28: 148814.38 | H28: 150914.06 | I28: 179908.13
B29: Capital Work in Progress | C29: 19496.83 | D29: 19007.4 | E29: 22045.55 | F29: 31213.02 | G29: 34355.53 | H29: 41622.35 | I29: 28496.71
B30: Investments | C30: 6285.18 | D30: 10681.93 | E30: 13139.85 | F30: 8410.31 | G30: 6257.57 | H30: 6194.11 | I30: 7088.85
B31: Other Assets | C31: 88816.45 | D31: 78444.68 | E31: 113948.44 | F31: 99150.99 | G31: 79884.94 | H31: 76728.06 | I31: 81020.93
B32: Total Assets | C32: 249149.12 | D32: 243909.19 | E32: 282421.67 | F32: 285395.78 | G32: 269312.42 | H32: 275458.58 | I32: 296514.62
B34: Working Capital | C34: 29571.83 | D34: -2724.33 | E34: 21531.16 | F34: 1730.36 | G34: -10309.6 | H34: -12759.84 | I34: -20944.36
... B37: Cash & Bank | C37: 8054.72 | D37: 5782.18 | E37: 15898.93 | F37: 13357.26 | G37: 8677.72 | H37: 11646.98 | I37: 10057.53
B39: JINDAL
B40: Rs Cr | C40: 43921 | D40: 44286 | E40: 44651 | F40: 45016 | G40: 45382 | H40: 45747 | I40: 46112
B41: Equity Share Capital | C41: 102 | D41: 102 | E41: 101.07 | F41: 100.5 | G41: 100.24 | H41: 101.18 | I41: 101.75
B42: Reserves | C42: 32035.14 | D42: 31712.67 | E42: 35523.59 | F42: 38606.09 | G42: 44215.77 | H42: 47083.7 | I42: 50797.16
B43: Borrowings | C43: 36824.37 | D43: 29909.69 | E43: 13501.64 | F43: 13046.31 | G43: 16472.14 | H43: 18406.08 | I43: 22609.55
B44: Other Liabilities | C44: 20780.44 | D44: 16116.07 | E44: 27517.24 | F44: 17674.33 | G44: 17887.88 | H44: 20174.68 | I44: 24126.48
B45: Total Liabilities | C45: 89741.95 | D45: 77840.43 | E45: 76643.54 | F45: 69427.23 | G45: 78676.03 | H45: 85765.64 | I45: 97634.94
B47: Net Block | C47: 69381.62 | D47: 54349.68 | E47: 45487.75 | F47: 43542.15 | G47: 48383.93 | H47: 48988.76 | I47: 64102.43
B48: Capital Work in Progress | C48: 3125.52 | D48: 1711.54 | E48: 2538.43 | F48: 7869.59 | G48: 9611.43 | H48: 16724.88 | I48: 8371.59
B49: Investments | C49: 180.59 | D49: 1155.54 | E49: 469.92 | F49: 907.4 | G49: 818.81 | H49: 2200.87 | I49: 3167.59
...

Sheet CASH FLOW 
B1: Rs Cr | C1: 43921 | D1: 44286 | E1: 44651 | F1: 45016 | G1: 45382 | H1: 45747 | I1: 46112
B2: Cash from Operating Activity (CFO) | C2: 12785 | D2: 18831 | E2: 26270 | F2: 23323 | G2: 12078 | H2: 20899 | I2: 25152 | J2: Coal prices 170% increased this leads to cost presure
B3: % Growth YoY | C3: -0.12628989 | D3: =D2/C2-1 -> 0.47289793 | E3: =E2/D2-1 -> 0.39504009 | F3: =F2/E2-1 -> -0.1121812 | G3: =G2/F2-1 -> -0.48214209 | H3: =H2/G2-1 -> 0.73033615 | I3: =I2/H2-1 -> 0.20350256
B4: Cash from Investing Activity | C4: -19589 | D4: -9410 | E4: -14748 | F4: -10730 | G4: -14467 | H4: -17012 | I4: 18560 | J4: 29278 other investing activity
B5: Cash from Financing Activity | C5: 5189 | D5: -1444 | E5: -14657 | F5: -5977 | G5: -5005 | H5: -262 | I5: -16111
B6: Net Cash Flow | C6: =C2+C4+C5 -> -1615 | D6: =D2+D4+D5 -> 7977 | E6: =E2+E4+E5 -> -3135 | F6: =F2+F4+F5 -> 6616 | G6: =G2+G4+G5 -> -7394 | H6: =H2+H4+H5 -> 3625 | I6: =I2+I4+I5 -> 27601
B7: CFO/Sales | C7: =C2/' P&L'!C2 -> 0.17435834 | D7: =D2/' P&L'!D2 -> 0.23586217 | E7: =E2/' P&L'!E2 -> 0.17947544 | F7: =F2/' P&L'!F2 -> 0.14053386 | G7: =G2/' P&L'!G2 -> 0.069014777 | H7: =H2/' P&L'!H2 -> 0.12379164 | I7: =I2/' P&L'!I2 -> 0.13561223
B8: CFO/Net Profit | C8: =C2/' P&L'!C29 -> 3.2623118 | D8: =D2/' P&L'!D29 -> 2.3918455 | E8: =E2/' P&L'!E29 -> 1.2546566 | F8: =F2/' P&L'!F29 -> 5.634936 | G8: =G2/' P&L'!G29 -> 1.3460381 | H8: =H2/' P&L'!H29 -> 5.9865368 | I8: =I2/' P&L'!I29 -> 0.98604359
B9: CFO/EBITDA | C9: =C2/' P&L'!C13 -> 1.0822822 | D9: =D2/' P&L'!D13 -> 0.93324413 | E9: =E2/' P&L'!E13 -> 0.67162653 | F9: =F2/' P&L'!F13 -> 1.2627504 | G9: =G2/' P&L'!G13 -> 0.42895195 | H9: =H2/' P&L'!H13 -> 0.91964796 | I9: =I2/' P&L'!I13 -> 0.85365191
B10: Capex | C10: 12767 | D10: 10915 | E10: 10048 | F10: 14749 | G10: 15547 | H10: 12635 | I10: 14542
B11: FCF | C11: =C2-C10 -> 18 | D11: =D2-D10 -> 7916 | E11: =E2-E10 -> 16222 | F11: =F2-F10 -> 8574 | G11: =G2-G10 -> -3469 | H11: =H2-H10 -> 8264 | I11: =I2-I10 -> 10610
B12: FCF Growth YoY | D12: =D11/C11-1 -> 438.77778 | E12: =E11/D11-1 -> 1.0492673 | F12: =F11/E11-1 -> -0.47145851 | G12: =G11/F11-1 -> -1.4045953 | H12: =H11/G11-1 -> -3.3822427 | I12: =I11/H11-1 -> 0.2838819
B13: FCF/Sales | C13: =C11/' P&L'!C2 -> 0.00024547909 | D13: =D11/' P&L'!D2 -> 0.099149538 | E13: =E11/' P&L'!E2 -> 0.11082796 | F13: =F11/' P&L'!F2 -> 0.051663051 | G13: =G11/' P&L'!G2 -> -0.019822178 | H13: =H11/' P&L'!H2 -> 0.048950386 | I13: =I11/' P&L'!I2 -> 0.057206017
B14: FCF/Net Profit | C14: =C11/' P&L'!C29 -> 0.0045930084 | D14: =D11/' P&L'!D29 -> 1.0054617 | E14: =E11/' P&L'!E29 -> 0.77476359 | F14: =F11/' P&L'!F29 -> 2.0715149 | G14: =G11/' P&L'!G29 -> -0.38660426 | H14: =H11/' P&L'!H29 -> 2.36723 | I14: =I11/' P&L'!I29 -> 0.41594794
B16: TATA
B17: Rs Cr | C17: 43921 | D17: 44286 | E17: 44651 | F17: 45016 | G17: 45382 | H17: 45747 | I17: 46112
B18: Cash from Operating Activity (CFO) | C18: 20168.72 | D18: 44326.68 | E18: 44380.99 | F18: 21683.08 | G18: 20300.67 | H18: 23137.58 | I18: 35064.46
B19: % Growth YoY | D19: =D18/C18-1 -> 1.1977934 | E19: =E18/D18-1 -> 0.0012252215 | F19: =F18/E18-1 -> -0.51143316 | G19: =G18/F18-1 -> -0.063755241 | H19: =H18/G18-1 -> 0.13974465 | I19: =I18/H18-1 -> 0.51547655
B20: Cash from Investing Activity | C20: -14012.06 | D20: -9437.27 | E20: -10905.02 | F20: -18179.45 | G20: -14252.74 | H20: -13611.02 | I20: -14397.35
B21: Cash from Financing Activity | C21: -1694.62 | D21: -37089.67 | E21: -23401.09 | F21: -6980.69 | G21: -11096.99 | H21: -7002.44 | I21: -21387.12
B22: Net Cash Flow | C22: =C18+C20+C21 -> 4462.04 | D22: =D18+D20+D21 -> -2200.26 | E22: =E18+E20+E21 -> 10074.88 | F22: =F18+F20+F21 -> -3477.06 | G22: =G18+G20+G21 -> -5049.06 | H22: =H18+H20+H21 -> 2524.12 | I22: =I18+I20+I21 -> -720.01
B23: CFO/Sales | C23: =C18/' P&L'!P2 -> 0.1442512 | D23: =D18/' P&L'!Q2 -> 0.28327848 | E23: =E18/' P&L'!R2 -> 0.18191975 | F23: =F18/' P&L'!S2 -> 0.08910146 | G23: =G18/' P&L'!T2 -> 0.088583152 | H23: =H18/' P&L'!U2 -> 0.10587222 | I23: =I18/' P&L'!V2 -> 0.1510488
B24: CFO/Net Profit | C24: =C18/' P&L'!P29 -> 17.184612 | D24: =D18/' P&L'!Q29 -> 5.4124318 | E24: =E18/' P&L'!R29 -> 1.063035 | F24: =F18/' P&L'!S29 -> 2.6850948 | G24: =G18/' P&L'!T29 -> -4.1348844 | H24: =H18/' P&L'!U29 -> 7.2902281 | I24: =I18/' P&L'!V29 -> 3.2211133
B25: CFO/EBITDA | C25: =C2/' P&L'!P13 -> 0.73211682 | D25: =D2/' P&L'!Q13 -> 0.61732361 | E25: =E2/' P&L'!R13 -> 0.41376627 | F25: =F2/' P&L'!S13 -> 0.72207073 | G25: =G2/' P&L'!T13 -> 0.54288221 | H25: =H2/' P&L'!U13 -> 0.82609804 | I25: =I2/' P&L'!V13 -> 0.73217507
B26: Capex | C26: 10012 | D26: 6534 | E26: 9953 | F26: 13814 | G26: 17732 | H26: 14407 | I26: 13158
B27: FCFF | C27: =C18-C26 -> 10156.72 | D27: =D18-D26 -> 37792.68 | E27: =E18-E26 -> 34427.99 | F27: =F18-F26 -> 7869.08 | G27: =G18-G26 -> 2568.67 | H27: =H18-H26 -> 8730.58 | I27: =I18-I26 -> 21906.46
B28: Average FCF (3 Years)
B29: FCF Growth YoY | D29: =D27/C27-1 -> 2.7209532 | E29: =E27/D27-1 -> -0.089030204 | F29: =F27/E27-1 -> -0.77143365 | G29: =G27/F27-1 -> -0.67357429 | H29: =H27/G27-1 -> 2.3988718 | I29: =I27/H27-1 -> 1.5091643
B30: FCF/Sales | C30: =C27/' P&L'!P2 -> 0.072643137 | D30: =D27/' P&L'!Q2 -> 0.24152165 | E30: =E27/' P&L'!R2 -> 0.14112193 | F30: =F27/' P&L'!S2 -> 0.032336113 | G30: =G27/' P&L'!T2 -> 0.011208541 | H30: =H27/' P&L'!U2 -> 0.039949116 | I30: =I27/' P&L'!V2 -> 0.094367475
B31: FCF/Net Profit | C31: =C27/' P&L'!P29 -> 8.6539599 | D31: =D27/' P&L'!Q29 -> 4.6146092 | E31: =E27/' P&L'!R29 -> 0.82463595 | F31: =F27/' P&L'!S29 -> 0.97445683 | G31: =G27/' P&L'!T29 -> -0.52319227 | H31: =H27/' P&L'!U29 -> 2.750846 | I31: =I27/' P&L'!V29 -> 2.0123849
B33: JINDAL
B34: Rs Cr | C34: 43921 | D34: 44286 | E34: 44651 | F34: 45016 | G34: 45382 | H34: 45747 | I34: 46112
B35: Cash from Operating Activity (CFO) | C35: 8814.32 | D35: 11960.93 | E35: 16047.77 | F35: 7347.41 | G35: 6008.35 | H35: 10823.96 | I35: 7204.23
B36: % Growth YoY | C36: -0.023548531 | D36: =D35/C35-1 -> 0.3569884 | E36: =E35/D35-1 -> 0.34168246 | F36: =F35/E35-1 -> -0.54215383 | G36: =G35/F35-1 -> -0.18224926 | H36: =H35/G35-1 -> 0.80148626 | I36: =I35/H35-1 -> -0.33441827
B37: Cash from Investing Activity | C37: -1475.61 | D37: -1884.23 | E37: -2331.32 | F37: -4090.4 | G37: -8344.07 | H37: -12322.78 | I37: -10733.93
B38: Cash from Financing Activity | C38: -7016.42 | D38: -4611.98 | E38: -15119.57 | F38: -2500.46 | G38: 1381.05 | H38: 809.41 | I38: 2802.51
B39: Net Cash Flow | C39: 322.29 | D39: 5464.72 | E39: -1403.12 | F39: 756.55 | G39: -954.67 | H39: -689.41 | I39: -727.19
B40: CFO/Sales | C40: 0.23242559 | D40: 0.34590256 | E40: 0.31364349 | F40: 0.13807931 | G40: 0.11932113 | H40: 0.21592359 | I40: 0.13477224
B41: CFO/Net Profit | C41: -22.052339 | D41: 2.8030977 | E41: 2.3718393 | F41: 1.8488283 | G41: 1.0109417 | H41: 3.8036462 | I41: 2.143561
B42: CFO/EBITDA | C42: 1.2903316 | D42: 0.91257717 | E42: 1.0314193 | F42: 0.73903182 | G42: 0.58896384 | H42: 1.1407704 | I42: 0.74239109
...

Sheet RATIOS 
B1: JSW | K1: TATA | T1: JINDAL
B2: Profitability Ratios | C2: 43921 | D2: 44286 | E2: 44651 | F2: 45016 | G2: 45382 | H2: 45747 | I2: 46112 | K2: Profitability Ratios | L2: 43921 | M2: 44286 | N2: 44651 | O2: 45016 | P2: 45382 | Q2: 45747 | R2: 46112 | T2: Profitability Ratios | U2: 43921 | V2: 44286 | W2: 44651 | X2: 45016 | Y2: 45382 | Z2: 45747 | AA2: 46112
B3: Sales Growth | D3: =' P&L'!D3 -> 0.088822519 | E3: 0.83332707 | F3: 0.13383116 | G3: 0.05450711 | H3: -0.035324503 | I3: 0.098599725 | K3: Sales Growth | M3: =' P&L'!Q3 -> 0.11916142 | N3: =' P&L'!R3 -> 0.55906968 | O3: =' P&L'!S3 -> -0.0024859898 | P3: =' P&L'!T3 -> -0.058277186 | Q3: =' P&L'!U3 -> -0.046377073 | R3: =' P&L'!V3 -> 0.062218696 | T3: Sales Growth | U3: -0.19253503 | V3: =' P&L'!AD3 -> -0.088185883 | W3: =' P&L'!AE3 -> 0.47967807 | X3: =' P&L'!AF3 -> 0.039985428 | Y3: =' P&L'!AG3 -> -0.053692697 | Z3: =' P&L'!AH3 -> -0.0044840128 | AA3: =' P&L'!AI3 -> 0.06635306
B4: Expenses Growth | D4: =' P&L'!D4/' P&L'!C4-1 -> -0.030107457 | E4: =' P&L'!E4/' P&L'!D4-1 -> 0.79777409 | F4: =' P&L'!F4/' P&L'!E4-1 -> 0.37510838 | G4: =' P&L'!G4/' P&L'!F4-1 -> -0.0043460574 | H4: =' P&L'!H4/' P&L'!G4-1 -> -0.0051072871 | I4: =' P&L'!I4/' P&L'!H4-1 -> 0.067810184 | K4: Expenses Growth | M4: =' P&L'!Q4/' P&L'!P4-1 -> 0.029582704 | N4: =' P&L'!R4/' P&L'!Q4-1 -> 0.43260079 | O4: =' P&L'!S4/' P&L'!R4-1 -> 0.16946552 | P4: =' P&L'!T4/' P&L'!S4-1 -> -0.019567024 | Q4: =' P&L'!U4/' P&L'!T4-1 -> -0.066105794 | R4: =' P&L'!V4/' P&L'!U4-1 -> 0.023511408 | T4: Expenses Growth | V4: =' P&L'!AD4/' P&L'!AC4-1 -> -0.30940296 | W4: =' P&L'!AE4/' P&L'!AD4-1 -> 0.65827533 | X4: =' P&L'!AF4/' P&L'!AE4-1 -> 0.21520825 | Y4: =' P&L'!AG4/' P&L'!AF4-1 -> -0.072029588 | Z4: =' P&L'!AH4/' P&L'!AG4-1 -> 0.012140596 | AA4: =' P&L'!AI4/' P&L'!AH4-1 -> 0.07653449
B5: Gross Profit Growth | D5: =' P&L'!D11/' P&L'!C11-1 -> 0.36872924 | E5: =' P&L'!E11/' P&L'!D11-1 -> 0.77723858 | F5: =' P&L'!F11/' P&L'!E11-1 -> -0.16179641 | G5: =' P&L'!G11/' P&L'!F11-1 -> 0.14662095 | H5: =' P&L'!H11/' P&L'!G11-1 -> -0.0074390669 | I5: =' P&L'!I11/' P&L'!H11-1 -> 0.17504237 | K5: Gross Profit Growth | M5: =' P&L'!Q11/' P&L'!P11-1 -> 0.23967633 | N5: =' P&L'!R11/' P&L'!Q11-1 -> 0.50806572 | O5: =' P&L'!S11/' P&L'!R11-1 -> -0.17089627 | P5: =' P&L'!T11/' P&L'!S11-1 -> 0.038727235 | Q5: =' P&L'!U11/' P&L'!T11-1 -> -0.062425231 | R5: =' P&L'!V11/' P&L'!U11-1 -> 0.13015215 | T5: Gross Profit Growth | V5: =' P&L'!AD11/' P&L'!AC11-1 -> -0.10658787 | W5: =' P&L'!AE11/' P&L'!AD11-1 -> 0.25974971 | X5: =' P&L'!AF11/' P&L'!AE11-1 -> -0.050772451 | Y5: =' P&L'!AG11/' P&L'!AF11-1 -> -0.0028527357 | Z5: =' P&L'!AH11/' P&L'!AG11-1 -> -0.02311766 | AA5: =' P&L'!AI11/' P&L'!AH11-1 -> -0.021519579
B6: EBITDA Growth | D6: =' P&L'!D13/' P&L'!C13-1 -> 0.70811817 | E6: =' P&L'!E13/' P&L'!D13-1 -> 0.93844781 | F6: =' P&L'!F13/' P&L'!E13-1 -> -0.52779056 | G6: =' P&L'!G13/' P&L'!F13-1 -> 0.52447212 | H6: =' P&L'!H13/' P&L'!G13-1 -> -0.19291828 | I6: =' P&L'!I13/' P&L'!H13-1 -> 0.29654565 | K6: EBITDA Growth | M6: =' P&L'!Q13/' P&L'!P13-1 -> 0.74678779 | N6: =' P&L'!R13/' P&L'!Q13-1 -> 1.081347 | O6: =' P&L'!S13/' P&L'!R13-1 -> -0.49125555 | P6: =' P&L'!T13/' P&L'!S13-1 -> -0.31121332 | Q6: =' P&L'!U13/' P&L'!T13-1 -> 0.13711529 | R6: =' P&L'!V13/' P&L'!U13-1 -> 0.35788714 | T6: EBITDA Growth | V6: =' P&L'!AD13/' P&L'!AC13-1 -> 0.91870357 | W6: =' P&L'!AE13/' P&L'!AD13-1 -> 0.18709124 | X6: =' P&L'!AF13/' P&L'!AE13-1 -> -0.36101349 | Y6: =' P&L'!AG13/' P&L'!AF13-1 -> 0.026113616 | Z6: =' P&L'!AH13/' P&L'!AG13-1 -> -0.069917738 | AA6: =' P&L'!AI13/' P&L'!AH13-1 -> 0.022743824
B7: EBIT Growth | D7: =' P&L'!D19/' P&L'!C19-1 -> 1.0482358 | E7: =' P&L'!E19/' P&L'!D19-1 -> 1.1364604 | F7: =' P&L'!F19/' P&L'!E19-1 -> -0.66792498 | G7: =' P&L'!G19/' P&L'!F19-1 -> 0.81747908 | H7: =' P&L'!H19/' P&L'!G19-1 -> -0.32869652 | I7: =' P&L'!I19/' P&L'!H19-1 -> 0.48054562 | K7: EBIT Growth | M7: =' P&L'!Q19/' P&L'!P19-1 -> 1.3575529 | N7: =' P&L'!R19/' P&L'!Q19-1 -> 1.5570049 | O7: =' P&L'!S19/' P&L'!R19-1 -> -0.57776524 | P7: =' P&L'!T19/' P&L'!S19-1 -> -0.46153793 | Q7: =' P&L'!U19/' P&L'!T19-1 -> 0.20308982 | R7: =' P&L'!V19/' P&L'!U19-1 -> 0.50552862 | T7: EBIT Growth | V7: =' P&L'!AD19/' P&L'!AC19-1 -> 2.142876 | W7: =' P&L'!AE19/' P&L'!AD19-1 -> 0.25901111 | X7: =' P&L'!AF19/' P&L'!AE19-1 -> -0.4613791 | Y7: =' P&L'!AG19/' P&L'!AF19-1 -> 0.01776585 | Z7: =' P&L'!AH19/' P&L'!AG19-1 -> -0.089307177 | AA7: =' P&L'!AI19/' P&L'!AH19-1 -> -0.027987989
B8: PBT Growth | D8: =' P&L'!D24/' P&L'!C24-1 -> 2.9877199 | E8: =' P&L'!E24/' P&L'!D24-1 -> 1.4756554 | F8: =' P&L'!F24/' P&L'!E24-1 -> -0.80988401 | G8: =' P&L'!G24/' P&L'!F24-1 -> 1.3660477 | H8: =' P&L'!H24/' P&L'!G24-1 -> -0.62055306 | I8: =' P&L'!I24/' P&L'!H24-1 -> 4.7612763 | K8: PBT Growth | M8: =' P&L'!Q24/' P&L'!P24-1 -> -10.9255 | N8: =' P&L'!R24/' P&L'!Q24-1 -> 2.6281418 | O8: =' P&L'!S24/' P&L'!R24-1 -> -0.63694493 | P8: =' P&L'!T24/' P&L'!S24-1 -> -1.0629028 | Q8: =' P&L'!U24/' P&L'!T24-1 -> -8.3344173 | R8: =' P&L'!V24/' P&L'!U24-1 -> 0.89812632 | T8: PBT Growth | V8: =' P&L'!AD24/' P&L'!AC24-1 -> -21.868155 | W8: =' P&L'!AE24/' P&L'!AD24-1 -> 0.5943944 | X8: =' P&L'!AF24/' P&L'!AE24-1 -> -0.45654245 | Y8: =' P&L'!AG24/' P&L'!AF24-1 -> 0.18511802 | Z8: =' P&L'!AH24/' P&L'!AG24-1 -> -0.30405991 | AA8: =' P&L'!AI24/' P&L'!AH24-1 -> 0.016023759
B9: Net Profit Growth | D9: =' P&L'!D29/' P&L'!C29-1 -> 1.0089308 | E9: =' P&L'!E29/' P&L'!D29-1 -> 1.6594691 | F9: =' P&L'!F29/' P&L'!E29-1 -> -0.80232114 | G9: =' P&L'!G29/' P&L'!F29-1 -> 1.167915 | H9: =' P&L'!H29/' P&L'!G29-1 -> -0.61094394 | I9: =' P&L'!I29/' P&L'!H29-1 -> 6.3067889 | K9: Net Profit Growth | M9: =' P&L'!Q29/' P&L'!P29-1 -> 5.9780514 | N9: =' P&L'!R29/' P&L'!Q29-1 -> 4.0977278 | O9: =' P&L'!S29/' P&L'!R29-1 -> -0.80657529 | P9: =' P&L'!T29/' P&L'!S29-1 -> -1.6079749 | Q9: =' P&L'!U29/' P&L'!T29-1 -> -1.6464424 | R9: =' P&L'!V29/' P&L'!U29-1 -> 2.4299227 | T9: Net Profit Growth | V9: =' P&L'!AD29/' P&L'!AC29-1 -> -11.675607 | W9: =' P&L'!AE29/' P&L'!AD29-1 -> 0.58563313 | X9: =' P&L'!AF29/' P&L'!AE29-1 -> -0.41263472 | Y9: =' P&L'!AG29/' P&L'!AF29-1 -> 0.49551721 | Z9: =' P&L'!AH29/' P&L'!AG29-1 -> -0.52119691 | AA9: =' P&L'!AI29/' P&L'!AH29-1 -> 0.18104284
B10: Dividend Growth | D10: =' P&L'!D43/' P&L'!C43-1 -> 2.3482181 | E10: =' P&L'!E43/' P&L'!D43-1 -> 1.6594691 | F10: =' P&L'!F43/' P&L'!E43-1 -> -0.80232114 | G10: =' P&L'!G43/' P&L'!F43-1 -> 1.1428272 | H10: =' P&L'!H43/' P&L'!G43-1 -> -0.62650619 | I10: =' P&L'!I43/' P&L'!H43-1 -> 2.0444954 | K10: Dividend Growth | M10: =' P&L'!Q43/' P&L'!P43-1 -> 2.5509488 | N10: =' P&L'!R43/' P&L'!Q43-1 -> 0.99783512 | O10: =' P&L'!S43/' P&L'!R43-1 -> -0.39596818 | P10: =' P&L'!T43/' P&L'!S43-1 -> 0.20233408 | Q10: =' P&L'!U43/' P&L'!T43-1 -> -0.16154502 | R10: =' P&L'!V43/' P&L'!U43-1 -> 0.20440033 | T10: Dividend Growth | V10: =IFERROR(' P&L'!AD43/' P&L'!AC43-1,0) -> 0 | W10: =IFERROR(' P&L'!AE43/' P&L'!AD43-1,0) -> 0 | X10: =IFERROR(' P&L'!AF43/' P&L'!AE43-1,0) -> -0.29516166 | Y10: =IFERROR(' P&L'!AG43/' P&L'!AF43-1,0) -> -0.25224139 | Z10: =IFERROR(' P&L'!AH43/' P&L'!AG43-1,0) -> 0.11720722 | AA10: =IFERROR(' P&L'!AI43/' P&L'!AH43-1,0) -> 0.012322438
B11: Dividend Payout | C11: =' P&L'!C44 -> 0.15 | D11: =' P&L'!D44 -> 0.25 | E11: =' P&L'!E44 -> 0.25 | F11: =' P&L'!F44 -> 0.25 | G11: =' P&L'!G44 -> 0.25 | H11: =' P&L'!H44 -> 0.24 | I11: =' P&L'!I44 -> 0.1 | K11: Dividend Payout | L11: =' P&L'!P44 -> 0.74 | M11: =' P&L'!Q44 -> 0.4 | N11: =' P&L'!R44 -> 0.16 | O11: =' P&L'!S44 -> 0.5 | P11: =' P&L'!T44 -> -1.01 | Q11: =' P&L'!U44 -> 1.31 | R11: =' P&L'!V44 -> 0.46 | T11: Dividend Payout | U11: =' P&L'!AC44 -> 0 | V11: =' P&L'!AD44 -> 0 | W11: =' P&L'!AE44 -> 0.05 | X11: =' P&L'!AF44 -> 0.06 | Y11: =' P&L'!AG44 -> 0.03 | Z11: =' P&L'!AH44 -> 0.07 | AA11: =' P&L'!AI44 -> 0.06
B12: Gross Margin | C12: =' P&L'!C12 -> 0.46812863 | D12: =' P&L'!D12 -> 0.5884718 | E12: =' P&L'!E12 -> 0.57046819 | F12: =' P&L'!F12 -> 0.42172813 | G12: =' P&L'!G12 -> 0.45856713 | H12: =' P&L'!H12 -> 0.47182273 | I12: =' P&L'!I12 -> 0.50465304 | K12: Gross Margin | L12: =' P&L'!P12 -> 0.58488499 | M12: =' P&L'!Q12 -> 0.6478673 | N12: =' P&L'!R12 -> 0.62667273 | O12: =' P&L'!S12 -> 0.52087158 | P12: =' P&L'!T12 -> 0.57452521 | Q12: =' P&L'!U12 -> 0.56485674 | R12: =' P&L'!V12 -> 0.60098176 | T12: Gross Margin | U12: =' P&L'!AC12 -> 0.70022353 | V12: =' P&L'!AD12 -> 0.68609181 | W12: =' P&L'!AE12 -> 0.58411622 | X12: =' P&L'!AF12 -> 0.53314132 | Y12: =' P&L'!AG12 -> 0.56178411 | Z12: =' P&L'!AH12 -> 0.55126887 | AA12: =' P&L'!AI12 -> 0.50584166
B13: Operating Margin | C13: =' P&L'!C20 -> 0.10319668 | D13: =' P&L'!D20 -> 0.19412818 | E13: =' P&L'!E20 -> 0.22622651 | F13: =' P&L'!F20 -> 0.066256929 | G13: =' P&L'!G20 -> 0.11419608 | H13: =' P&L'!H20 -> 0.079467374 | I13: =' P&L'!I20 -> 0.10709549 | K13: Operating Margin | L13: =' P&L'!P20 -> 0.064529725 | M13: =' P&L'!Q20 -> 0.13593413 | N13: =' P&L'!R20 -> 0.22294337 | O13: =' P&L'!S20 -> 0.094369041 | P13: =' P&L'!T20 -> 0.053958711 | Q13: =' P&L'!U20 -> 0.068074262 | R13: =' P&L'!V20 -> 0.096484603 | T13: Operating Margin | U13: =' P&L'!AC20 -> 0.08971239 | V13: =' P&L'!AD20 -> 0.30922412 | W13: =' P&L'!AE20 -> 0.26310899 | X13: =' P&L'!AF20 -> 0.1362673 | Y13: =' P&L'!AG20 -> 0.14655726 | Z13: =' P&L'!AH20 -> 0.13406981 | AA13: =' P&L'!AI20 -> 0.12220856
B14: PBT Margin | C14: =' P&L'!C26 -> 0.041090473 | D14: =' P&L'!D26 -> 0.15049036 | E14: =' P&L'!E26 -> 0.20321648 | F14: =' P&L'!F26 -> 0.034074476 | G14: =' P&L'!G26 -> 0.076454522 | H14: =' P&L'!H26 -> 0.030072738 | I14: =' P&L'!I26 -> 0.15770745 | K14: PBT Margin | L14: =' P&L'!P26 -> -0.0099756359 | M14: =' P&L'!Q26 -> 0.088470859 | N14: =' P&L'!R26 -> 0.20588228 | O14: =' P&L'!S26 -> 0.074932889 | P14: =' P&L'!T26 -> -0.0050051756 | Q14: =' P&L'!U26 -> 0.038495348 | R14: =' P&L'!V26 -> 0.068789067 | T14: PBT Margin | U14: =' P&L'!AC26 -> -0.0076799974 | V14: =' P&L'!AD26 -> 0.17576759 | W14: =' P&L'!AE26 -> 0.18939448 | X14: =' P&L'!AF26 -> 0.098970486 | Y14: =' P&L'!AG26 -> 0.12394674 | Z14: =' P&L'!AH26 -> 0.086648037 | AA14: =' P&L'!AI26 -> 0.082558458
B15: Net Margin | C15: =' P&L'!C31 -> 0.053446254 | D15: =' P&L'!D31 -> 0.098610955 | E15: =' P&L'!E31 -> 0.14304746 | F15: =' P&L'!F31 -> 0.024939745 | G15: =' P&L'!G31 -> 0.051272528 | H15: =' P&L'!H31 -> 0.02067834 | I15: =' P&L'!I31 -> 0.13753168 | K15: Net Margin | L15: =' P&L'!P31 -> 0.0083942077 | M15: =' P&L'!Q31 -> 0.052338485 | N15: =' P&L'!R31 -> 0.17113241 | O15: =' P&L'!S31 -> 0.03318373 | P15: =' P&L'!T31 -> -0.021423368 | Q15: =' P&L'!U31 -> 0.014522484 | R15: =' P&L'!V31 -> 0.046893352 | T15: Net Margin | U15: =' P&L'!AC31 -> -0.010539725 | V15: =' P&L'!AD31 -> 0.12340011 | W15: =' P&L'!AE31 -> 0.1322364 | X15: =' P&L'!AF31 -> 0.074684768 | Y15: =' P&L'!AG31 -> 0.11802969 | Z15: =' P&L'!AH31 -> 0.056767526 | AA15: =' P&L'!AI31 -> 0.06287306
B17: Efficiency Ratios | C17: 43921 | D17: 44286 | E17: 44651 | F17: 45016 | G17: 45382 | H17: 45747 | I17: 46112 | K17: Efficiency Ratios | L17: 43921 | M17: 44286 | N17: 44651 | O17: 45016 | P17: 45382 | Q17: 45747 | R17: 46112 | T17: Efficiency Ratios | U17: 43921 | V17: 44286 | W17: 44651 | X17: 45016 | Y17: 45382 | Z17: 45747 | AA17: 46112
B18: Debtor Days | C18: 22.424856 | D18: 20.508649 | E18: 18.595248 | F18: 15.689986 | G18: 15.742432 | H18: 18.193355 | I18: 22.159379 | J18: no customer-collection problem, | K18: Debtor Days | L18: 20.584045 | M18: 22.252681 | N18: 18.322521 | O18: 12.384875 | P18: 9.975916 | Q18: 8.7851187 | R18: 7.7309611 | T18: Debtor Days | U18: 34.160626 | V18: 29.496485 | W18: 9.0174881 | X18: 6.684296 | Y18: 12.065609 | Z18: 9.9235617 | AA18: 11.805945
B19: Debtor Turnover | C19: 16.276582 | D19: 17.79737 | E19: 19.628671 | F19: 23.263246 | G19: 23.185745 | H19: 20.06227 | I19: 16.471581 | K19: Debtor Turnover | L19: 17.732181 | M19: 16.402518 | N19: 19.92084 | O19: 29.471432 | P19: 36.588119 | Q19: 41.547532 | R19: 47.212758 | T19: Debtor Turnover | U19: 10.684816 | V19: 12.374356 | W19: 40.476904 | X19: 54.605601 | Y19: 30.251271 | Z19: 36.781149 | AA19: 30.916628
B20: Inventory Days | C20: 68.558833 | D20: 65.142161 | E20: 84.253404 | F20: 72.874638 | G20: 78.868582 | H20: 75.575392 | I20: 64.480644 | K20: Inventory Days | L20: 81.106812 | M20: 77.620658 | N20: 73.048709 | O20: 81.616503 | P20: 78.293102 | Q20: 74.472139 | R20: 74.291246 | T20: Inventory Days | U20: 61.297036 | V20: 62.727214 | W20: 51.942991 | X20: 40.379878 | Y20: 51.301127 | Z20: 40.849492 | AA20: 54.781017
B21: Inventory Turnover | C21: =' P&L'!C6/'BALANCE SHEET'!C17 -> 2.8316271 | D21: =' P&L'!D6/'BALANCE SHEET'!D17 -> 2.305846 | E21: =' P&L'!E6/'BALANCE SHEET'!E17 -> 1.8608045 | F21: =' P&L'!F6/'BALANCE SHEET'!F17 -> 2.8963332 | G21: =' P&L'!G6/'BALANCE SHEET'!G17 -> 2.5057252 | H21: =' P&L'!H6/'BALANCE SHEET'!H17 -> 2.5508926 | I21: =' P&L'!I6/'BALANCE SHEET'!I17 -> 2.8039676 | K21: Inventory Turnover | L21: =' P&L'!P6/'BALANCE SHEET'!C36 -> 1.8681165 | M21: =' P&L'!Q6/'BALANCE SHEET'!D36 -> 1.6558535 | N21: =' P&L'!R6/'BALANCE SHEET'!E36 -> 1.8653917 | O21: =' P&L'!S6/'BALANCE SHEET'!F36 -> 2.1427269 | P21: =' P&L'!T6/'BALANCE SHEET'!G36 -> 1.9835502 | Q21: =' P&L'!U6/'BALANCE SHEET'!H36 -> 2.1327075 | R21: =' P&L'!V6/'BALANCE SHEET'!I36 -> 1.9604148 | T21: Inventory Turnover | U21: 5.9546109 | V21: 5.8188461 | W21: 7.0269345 | X21: 9.0391555 | Y21: 7.1148534 | Z21: 8.9352396 | AA21: 6.662892
B22: Total Asset Turnover | C22: 0.55625853 | D22: 0.54252088 | E22: 0.74494745 | F22: 0.78826251 | G22: 0.76791372 | H22: 0.70213146 | I22: 0.68779714 | K22: Total Asset Turnover | L22: 0.56117658 | M22: 0.64153958 | N22: 0.8638118 | O22: 0.85268496 | P22: 0.85094768 | Q22: 0.79337703 | R22: 0.78289543 | T22: Total Asset Turnover | U22: 0.42258041 | V22: 0.44422802 | W22: 0.66757929 | X22: 0.76643588 | Y22: 0.64002276 | Z22: 0.58448418 | AA22: 0.54749714
B24: Leverage Ratios | C24: 43921 | D24: 44286 | E24: 44651 | F24: 45016 | G24: 45382 | H24: 45747 | I24: 46112 | K24: Leverage Ratios | L24: 43921 | M24: 44286 | N24: 44651 | O24: 45016 | P24: 45382 | Q24: 45747 | R24: 46112 | T24: Leverage Ratios | U24: 43921 | V24: 44286 | W24: 44651 | X24: 45016 | Y24: 45382 | Z24: 45747 | AA24: 46112
B25: Debt/Equity | C25: =('BALANCE SHEET'!C5)/('BALANCE SHEET'!C3+'BALANCE SHEET'!C4) -> 1.6782699 | D25: =('BALANCE SHEET'!D5)/('BALANCE SHEET'!D3+'BALANCE SHEET'!D4) -> 1.4629906 | E25: =('BALANCE SHEET'!E5)/('BALANCE SHEET'!E3+'BALANCE SHEET'!E4) -> 1.0734059 | F25: =('BALANCE SHEET'!F5)/('BALANCE SHEET'!F3+'BALANCE SHEET'!F4) -> 1.2307329 | G25: =('BALANCE SHEET'!G5)/('BALANCE SHEET'!G3+'BALANCE SHEET'!G4) -> 1.1328072 | H25: =('BALANCE SHEET'!H5)/('BALANCE SHEET'!H3+'BALANCE SHEET'!H4) -> 1.242226 | I25: =('BALANCE SHEET'!I5)/('BALANCE SHEET'!I3+'BALANCE SHEET'!I4) -> 0.99257394 | K25: Debt/Equity | L25: ='BALANCE SHEET'!C24/('BALANCE SHEET'!C22+'BALANCE SHEET'!C23) -> 1.5810553 | M25: ='BALANCE SHEET'!D24/('BALANCE SHEET'!D22+'BALANCE SHEET'!D23) -> 1.1921185 | N25: ='BALANCE SHEET'!E24/('BALANCE SHEET'!E22+'BALANCE SHEET'!E23) -> 0.66025291 | O25: ='BALANCE SHEET'!F24/('BALANCE SHEET'!F22+'BALANCE SHEET'!F23) -> 0.82354793 | P25: ='BALANCE SHEET'!G24/('BALANCE SHEET'!G22+'BALANCE SHEET'!G23) -> 0.94617701 | Q25: ='BALANCE SHEET'!H24/('BALANCE SHEET'!H22+'BALANCE SHEET'!H23) -> 1.0398315 | R25: ='BALANCE SHEET'!I24/('BALANCE SHEET'!I22+'BALANCE SHEET'!I23) -> 0.90421655 | T25: Debt/Equity | U25: ='BALANCE SHEET'!C43/('BALANCE SHEET'!C41+'BALANCE SHEET'!C42) -> 1.1458509 | V25: ='BALANCE SHEET'!D43/('BALANCE SHEET'!D41+'BALANCE SHEET'!D42) -> 0.94012259 | W25: ='BALANCE SHEET'!E43/('BALANCE SHEET'!E41+'BALANCE SHEET'!E42) -> 0.37899702 | X25: ='BALANCE SHEET'!F43/('BALANCE SHEET'!F41+'BALANCE SHEET'!F42) -> 0.33705656 | Y25: ='BALANCE SHEET'!G43/('BALANCE SHEET'!G41+'BALANCE SHEET'!G42) -> 0.37169727 | Z25: ='BALANCE SHEET'!H43/('BALANCE SHEET'!H41+'BALANCE SHEET'!H42) -> 0.39008428 | AA25: ='BALANCE SHEET'!I43/('BALANCE SHEET'!I41+'BALANCE SHEET'!I42) -> 0.44420499
B26: Debt/Assets | C26: ='BALANCE SHEET'!C5/'BALANCE SHEET'!C13 -> 0.46596116 | D26: ='BALANCE SHEET'!D5/'BALANCE SHEET'!D13 -> 0.4534224 | E26: ='BALANCE SHEET'!E5/'BALANCE SHEET'!E13 -> 0.36764639 | F26: ='BALANCE SHEET'!F5/'BALANCE SHEET'!F13 -> 0.38402861 | G26: ='BALANCE SHEET'!G5/'BALANCE SHEET'!G13 -> 0.38606745 | H26: ='BALANCE SHEET'!H5/'BALANCE SHEET'!H13 -> 0.41070515 | I26: ='BALANCE SHEET'!I5/'BALANCE SHEET'!I13 -> 0.3682813 | K26: Debt/Assets | L26: ='BALANCE SHEET'!C24/'BALANCE SHEET'!C32 -> 0.46690191 | M26: ='BALANCE SHEET'!D24/'BALANCE SHEET'!D32 -> 0.36284574 | N26: ='BALANCE SHEET'!E24/'BALANCE SHEET'!E32 -> 0.26754799 | O26: ='BALANCE SHEET'!F24/'BALANCE SHEET'!F32 -> 0.29745727 | P26: ='BALANCE SHEET'!G24/'BALANCE SHEET'!G32 -> 0.32334981 | Q26: ='BALANCE SHEET'!H24/'BALANCE SHEET'!H32 -> 0.34415719 | R26: ='BALANCE SHEET'!I24/'BALANCE SHEET'!I32 -> 0.3115586 | T26: Debt/Assets | U26: ='BALANCE SHEET'!C43/'BALANCE SHEET'!C51 -> 0.41033619 | V26: ='BALANCE SHEET'!D43/'BALANCE SHEET'!D51 -> 0.38424364 | W26: ='BALANCE SHEET'!E43/'BALANCE SHEET'!E51 -> 0.17616149 | X26: ='BALANCE SHEET'!F43/'BALANCE SHEET'!F51 -> 0.18791345 | Y26: ='BALANCE SHEET'!G43/'BALANCE SHEET'!G51 -> 0.20936669 | Z26: ='BALANCE SHEET'!H43/'BALANCE SHEET'!H51 -> 0.21460902 | AA26: ='BALANCE SHEET'!I43/'BALANCE SHEET'!I51 -> 0.23157232
B27: Debt/EBITDA | C27: ='BALANCE SHEET'!C5/' P&L'!C13 -> 5.1996106 | D27: ='BALANCE SHEET'!D5/' P&L'!D13 -> 3.3069184 | E27: ='BALANCE SHEET'!E5/' P&L'!E13 -> 1.8468323 | F27: ='BALANCE SHEET'!F5/' P&L'!F13 -> 4.3775311 | G27: ='BALANCE SHEET'!G5/' P&L'!G13 -> 3.1247647 | H27: ='BALANCE SHEET'!H5/' P&L'!H13 -> 4.3455226 | I27: ='BALANCE SHEET'!I5/' P&L'!I13 -> 3.3705539 | K27: Debt/EBITDA | L27: ='BALANCE SHEET'!C24/' P&L'!P13 -> 6.661387 | M27: ='BALANCE SHEET'!D24/' P&L'!Q13 -> 2.9012803 | N27: ='BALANCE SHEET'!E24/' P&L'!R13 -> 1.1901309 | O27: ='BALANCE SHEET'!F24/' P&L'!S13 -> 2.6282548 | P27: ='BALANCE SHEET'!G24/' P&L'!T13 -> 3.9141691 | Q27: ='BALANCE SHEET'!H24/' P&L'!U13 -> 3.7473067 | R27: ='BALANCE SHEET'!I24/' P&L'!V13 -> 2.689232 | T27: Debt/EBITDA | U27: ='BALANCE SHEET'!C43/' P&L'!AC13 -> 5.3907335 | V27: ='BALANCE SHEET'!D43/' P&L'!AD13 -> 2.2820049 | W27: ='BALANCE SHEET'!E43/' P&L'!AE13 -> 0.86777488 | X27: ='BALANCE SHEET'!F43/' P&L'!AF13 -> 1.3122499 | Y27: ='BALANCE SHEET'!G43/' P&L'!AG13 -> 1.6146687 | Z27: ='BALANCE SHEET'!H43/' P&L'!AH13 -> 1.9398733 | AA27: ='BALANCE SHEET'!I43/' P&L'!AI13 -> 2.329899
B28: Debt/Capital | C28: =('BALANCE SHEET'!C5)/('BALANCE SHEET'!C5+'BALANCE SHEET'!C3+'BALANCE SHEET'!C4) -> 0.62662464 | D28: =('BALANCE SHEET'!D5)/('BALANCE SHEET'!D5+'BALANCE SHEET'!D3+'BALANCE SHEET'!D4) -> 0.59398951 | E28: =('BALANCE SHEET'!E5)/('BALANCE SHEET'!E5+'BALANCE SHEET'!E3+'BALANCE SHEET'!E4) -> 0.51770178 | F28: =('BALANCE SHEET'!F5)/('BALANCE SHEET'!F5+'BALANCE SHEET'!F3+'BALANCE SHEET'!F4) -> 0.55171684 | G28: =('BALANCE SHEET'!G5)/('BALANCE SHEET'!G5+'BALANCE SHEET'!G3+'BALANCE SHEET'!G4) -> 0.53113436 | H28: =('BALANCE SHEET'!H5)/('BALANCE SHEET'!H5+'BALANCE SHEET'!H3+'BALANCE SHEET'!H4) -> 0.55401463 | I28: =('BALANCE SHEET'!I5)/('BALANCE SHEET'!I5+'BALANCE SHEET'!I3+'BALANCE SHEET'!I4) -> 0.49813656 | K28: Debt/Capital | L28: =('BALANCE SHEET'!C24)/('BALANCE SHEET'!C22+'BALANCE SHEET'!C23+'BALANCE SHEET'!C24) -> 0.61256158 | M28: =('BALANCE SHEET'!D24)/('BALANCE SHEET'!D22+'BALANCE SHEET'!D23+'BALANCE SHEET'!D24) -> 0.54382028 | N28: =('BALANCE SHEET'!E24)/('BALANCE SHEET'!E22+'BALANCE SHEET'!E23+'BALANCE SHEET'!E24) -> 0.39768213 | O28: =('BALANCE SHEET'!F24)/('BALANCE SHEET'!F22+'BALANCE SHEET'!F23+'BALANCE SHEET'!F24) -> 0.45161847 | P28: =('BALANCE SHEET'!G24)/('BALANCE SHEET'!G22+'BALANCE SHEET'!G23+'BALANCE SHEET'!G24) -> 0.48617212 | Q28: =('BALANCE SHEET'!H24)/('BALANCE SHEET'!H22+'BALANCE SHEET'!H23+'BALANCE SHEET'!H24) -> 0.50976342 | R28: =('BALANCE SHEET'!I24)/('BALANCE SHEET'!I22+'BALANCE SHEET'!I23+'BALANCE SHEET'!I24) -> 0.47484964 | T28: Debt/Capital | U28: ='BALANCE SHEET'!C43/('BALANCE SHEET'!C41+'BALANCE SHEET'!C42+'BALANCE SHEET'!C43) -> 0.53398439 | V28: ='BALANCE SHEET'!D43/('BALANCE SHEET'!D41+'BALANCE SHEET'!D42+'BALANCE SHEET'!D43) -> 0.48456865 | W28: ='BALANCE SHEET'!E43/('BALANCE SHEET'!E41+'BALANCE SHEET'!E42+'BALANCE SHEET'!E43) -> 0.27483527 | X28: ='BALANCE SHEET'!F43/('BALANCE SHEET'!F41+'BALANCE SHEET'!F42+'BALANCE SHEET'!F43) -> 0.25208848 | Y28: ='BALANCE SHEET'!G43/('BALANCE SHEET'!G41+'BALANCE SHEET'!G42+'BALANCE SHEET'!G43) -> 0.27097617 | Z28: ='BALANCE SHEET'!H43/('BALANCE SHEET'!H41+'BALANCE SHEET'!H42+'BALANCE SHEET'!H43) -> 0.28061916 | AA28: ='BALANCE SHEET'!I43/('BALANCE SHEET'!I41+'BALANCE SHEET'!I42+'BALANCE SHEET'!I43) -> 0.30757752
B29: CFO/Debt | C29: ='CASH FLOW '!C2/'BALANCE SHEET'!C5 -> 0.20814679 | D29: ='CASH FLOW '!D2/'BALANCE SHEET'!D5 -> 0.2822096 | E29: ='CASH FLOW '!E2/'BALANCE SHEET'!E5 -> 0.36366405 | F29: ='CASH FLOW '!F2/'BALANCE SHEET'!F5 -> 0.28846178 | G29: ='CASH FLOW '!G2/'BALANCE SHEET'!G5 -> 0.13727496 | H29: ='CASH FLOW '!H2/'BALANCE SHEET'!H5 -> 0.21163116 | I29: ='CASH FLOW '!I2/'BALANCE SHEET'!I5 -> 0.25326755 | K29: CFO/Debt | L29: ='CASH FLOW '!C18/'BALANCE SHEET'!C24 -> 0.17337774 | M29: ='CASH FLOW '!D18/'BALANCE SHEET'!D24 -> 0.50085846 | N29: ='CASH FLOW '!E18/'BALANCE SHEET'!E24 -> 0.58735041 | O29: ='CASH FLOW '!F18/'BALANCE SHEET'!F24 -> 0.25541643 | P29: ='CASH FLOW '!G18/'BALANCE SHEET'!G24 -> 0.23312099 | Q29: ='CASH FLOW '!H18/'BALANCE SHEET'!H24 -> 0.2440646 | R29: ='CASH FLOW '!I18/'BALANCE SHEET'!I24 -> 0.37956075 | T29: CFO/Debt | U29: ='CASH FLOW '!C35/'BALANCE SHEET'!C43 -> 0.23936105 | V29: ='CASH FLOW '!D35/'BALANCE SHEET'!D43 -> 0.3999015 | W29: ='CASH FLOW '!E35/'BALANCE SHEET'!E43 -> 1.1885793 | X29: ='CASH FLOW '!F35/'BALANCE SHEET'!F43 -> 0.56317917 | Y29: ='CASH FLOW '!G35/'BALANCE SHEET'!G43 -> 0.36475831 | Z29: ='CASH FLOW '!H35/'BALANCE SHEET'!H43 -> 0.58806438 | AA29: ='CASH FLOW '!I35/'BALANCE SHEET'!I43 -> 0.31863659
